<?xml version="1.0" ?>
<!-- =================================================================================== -->
<!-- |    This document was autogenerated by xacro from urdf/wheelchair_gazebo.xacro   | -->
<!-- |    EDITING THIS FILE BY HAND IS NOT RECOMMENDED                                 | -->
<!-- =================================================================================== -->
<robot name="wheelchair" xmlns:xacro="http://www.ros.org/wiki/xacro">
  <!-- From front wheel right joint to front wheel left joint -->
  <!-- From front wheel joint to back wheel joint -->
  <!-- From front wheel joint to head rest -->
  <link name="base_footprint">
    <visual>
      <origin rpy="0 0 0" xyz="0 0 0"/>
      <geometry>
        <mesh filename="package://simulator/meshes/wheelchair_rot.dae" scale="0.20 0.20 0.20"/>
        <!-- <box size="0.001 0.001 0.001"/> -->
      </geometry>
      <material
        name="">
        <color
          rgba="0.1 0.1 1 1" />
      </material>
    </visual>
  </link>

  <joint name="base_footprint_joint" type="fixed">
    <origin rpy="0 0 0" xyz=" 0 0 0.68"/>
    <parent link="base_footprint"/>
    <child link="base_link"/>
  </joint>
  
  <link name="base_link">
    <!-- <visual>
      <geometry>
        <box size="0.812 0.643 1.191"/>
      </geometry>
      <material name="white">
        <color rgba="1 1 1 1"/>
      </material>
    </visual> -->
    <collision>
      <geometry>
        <box size="0.812 0.643 1.191"/>
      </geometry>
    </collision>
    <inertial>
      <mass value="10.0"/>
      <inertia ixx="1.66916666667" ixy="0" ixz="0" iyy="1.2125" iyz="0" izz="1.52833333333"/>
    </inertial>
  </link>

  <!--Legs -->
  <!-- <link name="legs"> -->
    <!-- <visual>
      <geometry>
        <box size="0.4064 0.4064 0.4064"/>
      </geometry>
      <material name="white">
        <color rgba="1 1 1 1"/>
      </material>
    </visual> -->
    <!-- <collision>
      <geometry>
        <box size="0.4064 0.4064 0.4064"/>
      </geometry>
    </collision>
    <inertial>
      <mass value="2.0"/>
      <inertia ixx="0.135466666667" ixy="0" ixz="0" iyy="0.135466666667" iyz="0" izz="0.135466666667"/>
    </inertial>
  </link> -->

  <!-- <joint name="legs_joint" type="fixed">
    <axis xyz="0 0 0"/>
    <parent link="base_link"/>
    <child link="legs"/>
    <origin rpy="0 0 0" xyz="0.6092 0 -0.3923"/> -->
    <!--chair_height/4 + chair_height/8 because this is relative to the center of the bar -->
  <!-- </joint> -->

  <!--Right Bar -->
  <link name="right_bar">
    <!-- <visual>
      <geometry>
        <box size="1.015 0.16075 0.148875"/>
      </geometry>
      <material name="white">
        <color rgba="1 1 1 1"/>
      </material>
    </visual> -->
    <collision>
      <geometry>
        <box size="1.015 0.16075 0.148875"/>
      </geometry>
    </collision>
    <inertial>
      <mass value="2.0"/>
      <inertia ixx="1e-3" ixy="1e-3" ixz="1e-3" iyy="1e-3" iyz="1e-3" izz="1e-3"/>
    </inertial>
  </link>

  <joint name="right_bar_joint" type="fixed">
    <axis xyz="0 0 0"/>
    <parent link="base_link"/>
    <child link="right_bar"/>
    <origin rpy="0 0 0" xyz="0.0 0.3215 -0.446625"/>
    <!--chair_height/4 + chair_height/8 because this is relative to the center of the bar -->
  </joint>

  <!--Left Bar -->
  <link name="left_bar">
    <!-- <visual>
      <geometry>
        <box size="1.015 0.16075 0.148875"/>
      </geometry>
      <material name="white">
        <color rgba="1 1 1 1"/>
      </material>
    </visual> -->
    <collision>
      <geometry>
        <box size="1.015 0.16075 0.148875"/>
      </geometry>
    </collision>
    <inertial>
      <mass value="2.0"/>
      <inertia ixx="1e-3" ixy="1e-3" ixz="1e-3" iyy="1e-3" iyz="1e-3" izz="1e-3"/>
    </inertial>
  </link>

  <joint name="left_bar_joint" type="fixed">
    <axis xyz="0 0 0"/>
    <parent link="base_link"/>
    <child link="left_bar"/>
    <origin rpy="0 0 0" xyz="0.0 -0.3215 -0.446625"/>
    <!--chair_height/4 + chair_height/8 because this is relative to the center of the bar -->
  </joint>

  <!--Main Wheels -->
  <joint name="right_main_wheel_joint" type="continuous">
    <axis xyz="0 0 -1"/>
    <parent link="right_bar"/>
    <child link="right_main_wheel"/>
    <origin rpy="1.57075 0 0" xyz="0.0 0.0 -0.072875"/>
  </joint>

  <link name="right_main_wheel">
    <!-- <visual>
      <geometry>
        <cylinder length="0.065" radius="0.165"/>
      </geometry>
      <material name="white">
        <color rgba="0 0 0 1"/>
      </material>
    </visual> -->
    <collision>
      <geometry>
        <cylinder length="0.065" radius="0.165"/>
      </geometry>
    </collision>
    <inertial>
      <mass value="2.0"/>
      <inertia ixx="0.0143166666667" ixy="0" ixz="0" iyy="0.0143166666667" iyz="0" izz="0.027225"/>
    </inertial>
  </link>

  <joint name="left_main_wheel_joint" type="continuous">
    <axis xyz="0 0 -1"/>
    <parent link="left_bar"/>
    <child link="left_main_wheel"/>
    <origin rpy="1.57075 0 0" xyz="0.0 0.0 -0.072875"/>
  </joint>

  <link name="left_main_wheel">
    <!-- <visual>
      <geometry>
        <cylinder length="0.065" radius="0.165"/>
      </geometry>
      <material name="white">
        <color rgba="0 0 0 1"/>
      </material>
    </visual> -->
    <collision>
      <geometry>
        <cylinder length="0.065" radius="0.165"/>
      </geometry>
    </collision>
    <inertial>
      <mass value="2.0"/>
      <inertia ixx="0.0143166666667" ixy="0" ixz="0" iyy="0.0143166666667" iyz="0" izz="0.027225"/>
    </inertial>
  </link>
  
  <!--Front Wheels -->
  <link name="front_right_swivel">
    <!-- <visual>
      <geometry>
        <cylinder length="0.065" radius="0.01"/>
      </geometry>
      <material name="white">
        <color rgba="0 0 0 1"/>
      </material>
    </visual> -->
    <collision>
      <geometry>
        <cylinder length="0.065" radius="0.01"/>
      </geometry>
    </collision>
    <inertial>
      <mass value=".1"/>
      <inertia ixx="3.77083333333e-05" ixy="0" ixz="0" iyy="3.77083333333e-05" iyz="0" izz="5e-06"/>
    </inertial>
  </link>

  <joint name="front_right_swivel_joint" type="continuous">
    <axis xyz="0 0 1"/>
    <parent link="right_bar"/>
    <child link="front_right_swivel"/>
    <origin rpy="0 0 0" xyz="-0.406 0.0 -0.148875"/>
    <dynamics damping="0.0" friction="0.5"/>
  </joint>

  <joint name="front_right_wheel_joint" type="continuous">
    <axis xyz="0 0 1"/>
    <parent link="front_right_swivel"/>
    <child link="front_right_wheel"/>
    <origin rpy="1.57075 0 0" xyz="0.065 0 0"/>
    <dynamics damping="0.0" friction="0.5"/>
  </joint>

  <link name="front_right_wheel">
    <!-- <visual>
      <geometry>
        <cylinder length="0.05" radius="0.089"/>
      </geometry>
      <material name="white">
        <color rgba="0 0 0 1"/>
      </material>
    </visual> -->
    <collision>
      <geometry>
        <cylinder length="0.05" radius="0.089"/>
      </geometry>
      <surface>
        <friction>
          <ode>
            <mu>1.0</mu>
            <mu2>1.0</mu2>
          </ode>
        </friction>
      </surface>
    </collision>
    <inertial>
      <mass value="1.0"/>
      <inertia ixx="0.00218858333333" ixy="0" ixz="0" iyy="0.00218858333333" iyz="0" izz="0.0039605"/>
    </inertial>
  </link>

  <link name="front_left_swivel">
    <!-- <visual>
      <geometry>
        <cylinder length="0.065" radius="0.01"/>
      </geometry>
      <material name="white">
        <color rgba="0 0 0 1"/>
      </material>
    </visual> -->
    <collision>
      <geometry>
        <cylinder length="0.065" radius="0.01"/>
      </geometry>
    </collision>
    <inertial>
      <mass value=".1"/>
      <inertia ixx="3.77083333333e-05" ixy="0" ixz="0" iyy="3.77083333333e-05" iyz="0" izz="5e-06"/>
    </inertial>
  </link>

  <joint name="front_left_swivel_joint" type="continuous">
    <axis xyz="0 0 1"/>
    <parent link="left_bar"/>
    <child link="front_left_swivel"/>
    <origin rpy="0 0 0" xyz="-0.406 0.0 -0.148875"/>
    <dynamics damping="0.0" friction="0.5"/>
  </joint>

  <joint name="front_left_wheel_joint" type="continuous">
    <axis xyz="0 0 1"/>
    <parent link="front_left_swivel"/>
    <child link="front_left_wheel"/>
    <origin rpy="1.57075 0 0" xyz="0.065 0 0"/>
    <dynamics damping="0" friction="0.5"/>
  </joint>

  <link name="front_left_wheel">
    <!-- <visual>
      <geometry>
        <cylinder length="0.05" radius="0.089"/>
      </geometry>
      <material name="white">
        <color rgba="0 0 0 1"/>
      </material>
    </visual> -->
    <collision>
      <geometry>
        <cylinder length="0.05" radius="0.089"/>
      </geometry>
      <surface>
        <friction>
          <ode>
            <mu>1.0</mu>
            <mu2>1.0</mu2>
          </ode>
        </friction>
      </surface>
    </collision>
    <inertial>
      <mass value="1.0"/>
      <inertia ixx="0.00218858333333" ixy="0" ixz="0" iyy="0.00218858333333" iyz="0" izz="0.0039605"/>
    </inertial>
  </link>

  <!--Rear Wheels -->
  <link name="rear_right_swivel">
    <!-- <visual>
      <geometry>
        <cylinder length="0.065" radius="0.01"/>
      </geometry>
      <material name="white">
        <color rgba="0 0 0 1"/>
      </material>
    </visual> -->
    <collision>
      <geometry>
        <cylinder length="0.065" radius="0.01"/>
      </geometry>
    </collision>
    <inertial>
      <mass value=".1"/>
      <inertia ixx="3.77083333333e-05" ixy="0" ixz="0" iyy="3.77083333333e-05" iyz="0" izz="5e-06"/>
    </inertial>
  </link>

  <joint name="rear_right_swivel_joint" type="continuous">
    <axis xyz="0 0 1"/>
    <parent link="right_bar"/>
    <child link="rear_right_swivel"/>
    <origin rpy="0 0 0" xyz="0.406 0.0 -0.148875"/>
    <dynamics damping="0.0" friction="0.5"/>
  </joint>

  <joint name="rear_right_wheel_joint" type="continuous">
    <axis xyz="0 0 1"/>
    <parent link="rear_right_swivel"/>
    <child link="rear_right_wheel"/>
    <origin rpy="1.57075 0 0" xyz="0.065 0 0"/>
    <dynamics damping="0" friction="0.5"/>
  </joint>

  <link name="rear_right_wheel">
    <!-- <visual>
      <geometry>
        <cylinder length="0.05" radius="0.089"/>
      </geometry>
      <material name="white">
        <color rgba="0 0 0 1"/>
      </material>
    </visual> -->
    <collision>
      <geometry>
        <cylinder length="0.05" radius="0.089"/>
      </geometry>
      <surface>
        <friction>
          <ode>
            <mu>1.0</mu>
            <mu2>1.0</mu2>
          </ode>
        </friction>
      </surface>
    </collision>
    <inertial>
      <mass value="1.0"/>
      <inertia ixx="0.00218858333333" ixy="0" ixz="0" iyy="0.00218858333333" iyz="0" izz="0.0039605"/>
    </inertial>
  </link>

  <link name="rear_left_swivel">
    <!-- <visual>
      <geometry>
        <cylinder length="0.065" radius="0.01"/>
      </geometry>
      <material name="white">
        <color rgba="0 0 0 1"/>
      </material>
    </visual> -->
    <collision>
      <geometry>
        <cylinder length="0.065" radius="0.01"/>
      </geometry>
    </collision>
    <inertial>
      <mass value=".1"/>
      <inertia ixx="3.77083333333e-05" ixy="0" ixz="0" iyy="3.77083333333e-05" iyz="0" izz="5e-06"/>
    </inertial>
  </link>

  <joint name="rear_left_swivel_joint" type="continuous">
    <axis xyz="0 0 1"/>
    <parent link="left_bar"/>
    <child link="rear_left_swivel"/>
    <origin rpy="0 0 0" xyz="0.406 0.0 -0.148875"/>
    <dynamics damping="0.0" friction="0.5"/>
  </joint>

  <joint name="rear_left_wheel_joint" type="continuous">
    <axis xyz="0 0 1"/>
    <parent link="rear_left_swivel"/>
    <child link="rear_left_wheel"/>
    <origin rpy="1.57075 0 0" xyz="0.065 0 0"/>
    <dynamics damping="0" friction="0.5"/>
  </joint>

  <link name="rear_left_wheel">
    <!-- <visual>
      <geometry>
        <cylinder length="0.05" radius="0.089"/>
      </geometry>
      <material name="white">
        <color rgba="0 0 0 1"/>
      </material>
    </visual> -->
    <collision>
      <geometry>
        <cylinder length="0.05" radius="0.089"/>
      </geometry>
      <surface>
        <friction>
          <ode>
            <mu>1.0</mu>
            <mu2>1.0</mu2>
          </ode>
        </friction>
      </surface>
    </collision>
    <inertial>
      <mass value="1.0"/>
      <inertia ixx="0.00218858333333" ixy="0" ixz="0" iyy="0.00218858333333" iyz="0" izz="0.0039605"/>
    </inertial>
  </link>

<!-- camera -->
  <link name='camera_link'>
    <pose>0 0 0 0 0 0</pose>
    <inertial>
      <mass value="0.1"/>
      <origin xyz="0 0 0" rpy=" 0 0 0"/>
      <inertia
          ixx="1e-6" ixy="0" ixz="0"
          iyy="1e-6" iyz="0"
          izz="1e-6"
      />
    </inertial>

    <collision name='collision'>
      <origin xyz="0 0 0" rpy=" 0 0 0"/> 
      <geometry>
        <box size=".05 .05 .05"/>
      </geometry>
    </collision>

    <visual name='camera_link_visual'>
      <origin xyz="0 0 0" rpy=" 0 0 0"/>
      <geometry>
        <box size=".05 .05 .05"/>
      </geometry>
    </visual>

  </link>
 
 <link name="camera_link_optical">
  </link>


  <joint type="fixed" name="camera_optical_joint">
    <origin xyz="0 0 0" rpy="-1.5707 0 -1.5707"/>
    <child link="camera_link_optical"/>
    <parent link="camera_link"/>
  </joint>
  
 <joint type="fixed" name="camera_joint">
    <origin xyz="0.35 0 -0.2" rpy="0 0 0"/>
    <child link="camera_link"/>
    <parent link="base_link"/>
    <axis xyz="0 1 0" rpy="0 0 0"/>
  </joint>

<transmission name="left_wheel_transmission">
  <type>transmission_interface/SimpleTransmission</type>
  <joint name="left_main_wheel_joint">
    <hardwareInterface>hardware_interface/VelocityJointInterface</hardwareInterface>  
  </joint>
  <actuator name="left_wheel_actuator">
    <mechanicalReduction>7</mechanicalReduction>
    <hardwareInterface>VelocityJointInterface</hardwareInterface>
  </actuator>
</transmission>

<transmission name="right_wheel_transmission">
  <type>transmission_interface/SimpleTransmission</type>
  <joint name="right_main_wheel_joint">
    <hardwareInterface>hardware_interface/VelocityJointInterface</hardwareInterface>  
  </joint>
  <actuator name="right_wheel_actuator">
    <mechanicalReduction>7</mechanicalReduction>
    <hardwareInterface>VelocityJointInterface</hardwareInterface>
  </actuator>
</transmission>


<gazebo>
    <plugin name="mobile_base_controller" filename="libgazebo_ros_diff_drive.so">
      <commandTopic>cmd_vel</commandTopic>
      <odometryTopic>odom</odometryTopic>
      <odometryFrame>odom</odometryFrame>
      <odometrySource>world</odometrySource>
      <publishOdomTF>true</publishOdomTF>
      <robotBaseFrame>base_footprint</robotBaseFrame>
      <publishWheelTF>false</publishWheelTF>
      <publishTf>true</publishTf>
      <publishWheelJointState>true</publishWheelJointState>
      <legacyMode>false</legacyMode>
      <updateRate>30</updateRate>
      <leftJoint>right_main_wheel_joint</leftJoint>
      <rightJoint>left_main_wheel_joint</rightJoint>
      <wheelSeparation>0.643</wheelSeparation>
      <wheelDiameter>0.66</wheelDiameter>
      <wheelAcceleration>6</wheelAcceleration>
      <wheelTorque>50</wheelTorque>
      <rosDebugLevel>na</rosDebugLevel>
    </plugin>
  </gazebo>

<!--camera-->
  <gazebo reference="camera">
    <material>Gazebo/Red</material>
  </gazebo>

<!-- RGBD Camera -->
<gazebo reference="camera_link">
    <sensor type="depth" name="camera1">
      <always_on>1</always_on>
      <update_rate>20.0</update_rate>
      <visualize>true</visualize>             
      <camera>
        <horizontal_fov>1.047</horizontal_fov>  
        <image>
          <width>640</width>
          <height>480</height>
          <format>R8G8B8</format>
        </image>
        <depth_camera>

        </depth_camera>
        <clip>
          <near>0.1</near>
          <far>20</far>
        </clip>
      </camera>

      <plugin name="camera_controller" filename="libgazebo_ros_openni_kinect.so">
        <alwaysOn>true</alwaysOn>
        <updateRate>10.0</updateRate>
        <cameraName>camera</cameraName>
        <frameName>camera_link_optical</frameName>                   
        <imageTopicName>/camera/color/image_raw</imageTopicName>
        <depthImageTopicName>/camera/aligned_depth_to_color/image_raw</depthImageTopicName>
        <pointCloudTopicName>/camera/aligned_depth_to_color/depth/points</pointCloudTopicName>
        <cameraInfoTopicName>/camera/color/camera_info</cameraInfoTopicName>              
        <depthImageCameraInfoTopicName>/camera/depth/camera_info</depthImageCameraInfoTopicName>            
        <pointCloudCutoff>0.4</pointCloudCutoff>                
          <hackBaseline>0.07</hackBaseline>
          <distortionK1>0.0</distortionK1>
          <distortionK2>0.0</distortionK2>
          <distortionK3>0.0</distortionK3>
          <distortionT1>0.0</distortionT1>
          <distortionT2>0.0</distortionT2>
        <CxPrime>0.0</CxPrime>
        <Cx>0.0</Cx>
        <Cy>0.0</Cy>
        <focalLength>0.0</focalLength>
      </plugin>

    </sensor>
  </gazebo>

  <!-- this color take effect only on rviz -->
  <material name="WHITE_MTL">
    <color rgba="${255/255} ${108/255} ${10/255} 1.0"/>
  </material>

  <gazebo reference="base_footprint"> <!-- reference to a existing "link" -->
    <!-- NOTE: use Gazebo/DepthMap to take color from mesh (.dae only) -->
    <material>Gazebo/Grey</material>
  </gazebo>


</robot>

